Workbook

Sheet P&L Input
B1: P&L Input
B3: (in ₦'millions) | C3: 31 Dec 2021 | D3: 31 Dec 2022 | E3: 31 Dec 2023 | F3: 31 Dec 2024 | G3: 31 Dec 2025
B4: Revenue | C4: 1383637 | D4: 1618323 | E4: 2208090 | F4: 3580550 | G4: 4306704
B5: Production cost of sales | C5: -551019 | D5: -662890 | E5: -1006278 | F5: -1645651 | G5: -1634430
B6: Gross profit | C6: =C4+C5 -> 832618 | D6: =D4+D5 -> 955433 | E6: =E4+E5 -> 1201812 | F6: =F4+F5 -> 1934899 | G6: =G4+G5 -> 2672274
B7: Administrative expenses | C7: -64349 | D7: -79879 | E7: -126533 | F7: -220537 | G7: -261761
B8: Selling and distribution expenses | C8: -191658 | D8: -295234 | E8: -365105 | F8: -618664 | G8: -682763
B9: Other income | C9: 6221 | D9: 5333 | E9: 24953 | F9: 57070 | G9: 42251
B10: Impairment of financial assets | C10: -341 | D10: 223 | E10: -860 | F10: -726 | G10: -4724
B11: EBIT (Operating income) | C11: =SUM(C6:C10) -> 582491 | D11: =SUM(D6:D10) -> 585876 | E11: =SUM(E6:E10) -> 734267 | F11: =SUM(F6:F10) -> 1152042 | G11: =SUM(G6:G10) -> 1765277
B12: Finance income | C12: 20765 | D12: 38715 | E12: 27405 | F12: 168572 | G12: 109942
B13: Finance costs | C13: -65707 | D13: -130370 | E13: -310962 | F13: -700299 | G13: -351504
B14: Gain on net monetary position | C14: 0 | D14: 29022 | E14: 101163 | F14: 109404 | G14: 6452
B15: Share of profit from associate | C15: 817 | D15: 759 | E15: 1231 | F15: 2818 | G15: 2493
B16: EBT (Income before tax) | C16: =SUM(C11:C15) -> 538366 | D16: =SUM(D11:D15) -> 524002 | E16: =SUM(E11:E15) -> 553104 | F16: =SUM(F11:F15) -> 732537 | G16: =SUM(G11:G15) -> 1532660
B17: Income tax expense | C17: -173927 | D17: -141691 | E17: -97521 | F17: -229290 | G17: -517739
B18: Net income | C18: =C16+C17 -> 364439 | D18: =D16+D17 -> 382311 | E18: =E16+E17 -> 455583 | F18: =F16+F17 -> 503247 | G18: =G16+G17 -> 1014921
B20: KPIs
B21: Revenue % y-o-y | D21: =D4/C4-1 -> 0.1696153 | E21: =E4/D4-1 -> 0.36443096 | F21: =F4/E4-1 -> 0.62155981 | G21: =G4/F4-1 -> 0.20280516
B22: Gross Profit % | C22: =C6/C4 -> 0.60176043 | D22: =D6/D4 -> 0.59038461 | E22: =E6/E4 -> 0.54427673 | F22: =F6/F4 -> 0.54039156 | G22: =G6/G4 -> 0.62049168
B23: EBIT % | C23: =C11/C4 -> 0.42098542 | D23: =D11/D4 -> 0.36202662 | E23: =E11/E4 -> 0.33253491 | F23: =F11/F4 -> 0.32175001 | G23: =G11/G4 -> 0.40989049
B24: Net Income % | C24: =C18/C4 -> 0.26339206 | D24: =D18/D4 -> 0.236239 | E24: =E18/E4 -> 0.20632447 | F24: =F18/F4 -> 0.14055019 | G24: =G18/G4 -> 0.23566073
B25: ROA | C25: =C18/'Balance Sheet Input'!C20 -> 0.15235623 | D25: =D18/'Balance Sheet Input'!D20 -> 0.14616262 | E25: =E18/'Balance Sheet Input'!E20 -> 0.11566763 | F25: =F18/'Balance Sheet Input'!F20 -> 0.078592581 | G25: =G18/'Balance Sheet Input'!G20 -> 0.16801306
B26: ROE | C26: =C18/'Balance Sheet Input'!C34 -> 0.37751225 | D26: =D18/'Balance Sheet Input'!D34 -> 0.36259697 | E26: =E18/'Balance Sheet Input'!E34 -> 0.2694109 | F26: =F18/'Balance Sheet Input'!F34 -> 0.23715212 | G26: =G18/'Balance Sheet Input'!G34 -> 0.40270871

Sheet Balance Sheet Input
B1: Balance Sheet Input
B3: (in ₦'millions) | C3: 31 Dec 2021 | D3: 31 Dec 2022 | E3: 31 Dec 2023 | F3: 31 Dec 2024 | G3: 31 Dec 2025
B4: Inventories | C4: 167205 | D4: 239563 | E4: 394023 | F4: 669662 | G4: 756835
B5: Trade and other receivables | C5: 47469 | D5: 45490 | E5: 73215 | F5: 116742 | G5: 147472
B6: Prepayments and other current assets | C6: 311722 | D6: 447149 | E6: 488676 | F6: 665071 | G6: 663611
B7: Lease receivables | C7: 3752 | D7: 5981 | E7: 4059 | F7: 7889 | G7: 4897
B8: Current tax assets | C8: 3051 | D8: 1435 | E8: 1944 | F8: 1826 | G8: 1573
B9: Cash and cash equivalents | C9: 339843 | D9: 283843 | E9: 447097 | F9: 449831 | G9: 397569
B10: Total current assets | C10: =SUM(C4:C9) -> 873042 | D10: =SUM(D4:D9) -> 1023461 | E10: =SUM(E4:E9) -> 1409014 | F10: =SUM(F4:F9) -> 1911021 | G10: =SUM(G4:G9) -> 1971957
B11: Property, plant and equipment | C11: 1472859 | D11: 1527293 | E11: 2383528 | F11: 3271322 | G11: 3917363
B12: Intangible assets | C12: 5122 | D12: 6225 | E12: 12356 | F12: 17003 | G12: 16383
B13: Right-of-use assets | C13: 18566 | D13: 23551 | E13: 51319 | F13: 70429 | G13: 62032
B14: Investments in subsidiaries | C14: 0 | D14: 0 | E14: 0 | F14: 0 | G14: 0
B15: Investment in associate | C15: 6528 | D15: 2580 | E15: 2607 | F15: 3005 | G15: 3222
B16: Lease receivables | C16: 5980 | D16: 17085 | E16: 14656 | F16: 16877 | G16: 23044
B17: Deferred tax assets | C17: 5163 | D17: 14193 | E17: 25933 | F17: 19426 | G17: 17757
B18: Prepayments | C18: 4759 | D18: 1267 | E18: 39312 | F18: 48580 | G18: 28969
B19: Receivables from related parties | C19: 0 | D19: 0 | E19: 0 | F19: 1045575 | G19: 0
B20: Total assets | C20: =SUM(C10:C19) -> 2392019 | D20: =SUM(D10:D19) -> 2615655 | E20: =SUM(E10:E19) -> 3938725 | F20: =SUM(F10:F19) -> 6403238 | G20: =SUM(G10:G19) -> 6040727
B21: Trade and other payables | C21: 371224 | D21: 334899 | E21: 619901 | F21: 992119 | G21: 1269622
B22: Lease liabilities | C22: 2187 | D22: 1713 | E22: 4099 | F22: 5860 | G22: 6221
B23: Current tax liabilities | C23: 153385 | D23: 167971 | E23: 174287 | F23: 183160 | G23: 297021
B24: Financial liabilities | C24: 401393 | D24: 392378 | E24: 624256 | F24: 1245181 | G24: 799765
B25: Other current liabilities | C25: 148294 | D25: 124724 | E25: 190089 | F25: 143264 | G25: 231065
B26: Total current liabilities | C26: =SUM(C21:C25) -> 1076483 | D26: =SUM(D21:D25) -> 1021685 | E26: =SUM(E21:E25) -> 1612632 | F26: =SUM(F21:F25) -> 2569584 | G26: =SUM(G21:G25) -> 2603694
B27: Deferred tax liabilities | C27: 135003 | D27: 154026 | E27: 161483 | F27: 196422 | G27: 353245
B28: Financial liabilities | C28: 176562 | D28: 333498 | E28: 388364 | F28: 1386383 | G28: 359810
B29: Lease liabilities | C29: 8019 | D29: 8057 | E29: 16505 | F29: 26317 | G29: 24597
B30: Provisions | C30: 8428 | D30: 10575 | E30: 21200 | F30: 31931 | G30: 57427
B31: Deferred revenue | C31: 636 | D31: 320 | E31: 510 | F31: 756 | G31: 708
B32: Employee benefit obligations | C32: 3219 | D32: 8547 | E32: 12191 | F32: 16600 | G32: 21110
B33: Total liabilities | C33: =SUM(C26:C32) -> 1408350 | D33: =SUM(D26:D32) -> 1536708 | E33: =SUM(E26:E32) -> 2212885 | F33: =SUM(F26:F32) -> 4227993 | G33: =SUM(G26:G32) -> 3420591
B34: Total stockholders' equity | C34: 965370 | D34: 1054369 | E34: 1691034 | F34: 2122043 | G34: 2520236
B35: Non-controlling interest | C35: 18299 | D35: 24578 | E35: 34806 | F35: 53202 | G35: 99900
B36: Total equity and liabilities | C36: =SUM(C33:C35) -> 2392019 | D36: =SUM(D33:D35) -> 2615655 | E36: =SUM(E33:E35) -> 3938725 | F36: =SUM(F33:F35) -> 6403238 | G36: =SUM(G33:G35) -> 6040727
B38: KPIs
B39: Liquidity ratios
B40: Quick ratio | C40: =(C9+C5)/C26 -> 0.35979388 | D40: =(D9+D5)/D26 -> 0.32234299 | E40: =(E9+E5)/E26 -> 0.3226477 | F40: =(F9+F5)/F26 -> 0.22049211 | G40: =(G9+G5)/G26 -> 0.20933374
B41: Current ratio | C41: =C10/C26 -> 0.81101327 | D41: =D10/D26 -> 1.0017383 | E41: =E10/E26 -> 0.87373561 | F41: =F10/F26 -> 0.74370832 | G41: =G10/G26 -> 0.75736895
B42: DSO | C42: =C5/'P&L Input'!C4*360 -> 12.350667 | D42: =D5/'P&L Input'!D4*360 -> 10.119364 | E42: =E5/'P&L Input'!E4*360 -> 11.936742 | F42: =F5/'P&L Input'!F4*360 -> 11.737616 | G42: =G5/'P&L Input'!G4*360 -> 12.327274
...

Sheet Forecast
B1: Dangote Cement Group — Revenue & Net Income Forecast
B3: HISTORICAL DATA
B4: Year | C4: Revenue (₦'m) | D4: Net Income (₦'m) | E4: Revenue Growth % | F4: Net Income Growth %
B5: 2021 | C5: ='P&L Input'!C$4 -> 1383637 | D5: ='P&L Input'!C$18 -> 364439
B6: 2022 | C6: ='P&L Input'!D$4 -> 1618323 | D6: ='P&L Input'!D$18 -> 382311 | E6: =(C6-C5)/C5 -> 0.1696153 | F6: =(D6-D5)/D5 -> 0.049039757
B7: 2023 | C7: ='P&L Input'!E$4 -> 2208090 | D7: ='P&L Input'!E$18 -> 455583 | E7: =(C7-C6)/C6 -> 0.36443096 | F7: =(D7-D6)/D6 -> 0.19165548
B8: 2024 | C8: ='P&L Input'!F$4 -> 3580550 | D8: ='P&L Input'!F$18 -> 503247 | E8: =(C8-C7)/C7 -> 0.62155981 | F8: =(D8-D7)/D7 -> 0.10462199
B9: 2025 | C9: ='P&L Input'!G$4 -> 4306704 | D9: ='P&L Input'!G$18 -> 1014921 | E9: =(C9-C8)/C8 -> 0.20280516 | F9: =(D9-D8)/D8 -> 1.0167453
B11: Average Revenue Growth (2021–2025) | D11: =AVERAGE(E6:E9) -> 0.3396028
B12: Average Net Income Growth (2021–2025) | D12: =AVERAGE(F6:F9) -> 0.34051562
B14: FORECAST (2026–2027)
B15: Year | C15: Method 1 — FORECAST.LINEAR (₦'m) | D15: Method 2 — Avg Growth Rate (₦'m) | E15: Blended Forecast (₦'m) | F15: Net Income Forecast — Avg Growth (₦'m)
B16: 2026 | C16: =_xlfn.FORECAST.LINEAR(B16,$C$5:$C$9,$B$5:$B$9) -> 4961969.1 | D16: =C9*(1+$D$11) -> 5769272.8 | E16: =AVERAGE(C16,D16) -> 5365620.9 | F16: =D9*(1+$D$12) -> 1360517.5
B17: 2027 | C17: =_xlfn.FORECAST.LINEAR(B17,$C$5:$C$9,$B$5:$B$9) -> 5742805.2 | D17: =C16*(1+$D$11) -> 6647067.7 | E17: =AVERAGE(C17,D17) -> 6194936.5 | F17: =F16*(1+$D$12) -> 1823794.9
B19: FORECAST ASSUMPTIONS & METHODOLOGY
B20: Method 1 — FORECAST.LINEAR projects revenue using
B21: Excel's linear regression across all 5 historical
B22: data points (2021–2025).
B23: Method 2 — Average Growth Rate applies the mean
B24: annual revenue growth rate consistently forward
B25: from the 2025 base year.
B26: Blended Forecast — simple average of both methods
B27: to reduce single-method bias.
B28: Key assumption — forecasts assume continuation of
B29: current business conditions. Significant macro
B30: changes (FX volatility, fuel prices, regulatory
... B34: Analyst — Nwankwo Emmanuel

Sheet Dashboard
B2: DANGOTE CEMENT PLC GROUP — FINANCIAL PERFORMANCE & FORECAST DASHBOARD
B3: Source: Dangote Cement Plc Group Annual Reports 2021–2025 | Analyst: Nwankwo Emmanuel | github.com/Emmapluz
B5: REVENUE TREND + FORECAST (2021-2027) | F5: PROFITABILITY MARGINS (2021-2025)
B28: KEY FINANCIAL METRICS SUMMARY | F28: KEY FINDINGS & STRATEGIC INSIGHTS
B40: Data source: Dangote Cement Plc Group Annual Reports 2021–2025
B41: | Nigerian Exchange Group (NGX) | Analyst: Nwankwo Emmanuel
Z45: Metric | AA45: 2021 | AB45: 2022 | AC45: 2023 | AD45: 2024 | AE45: 2025 | AF45: 2026 | AG45: 2027
Z46: Revenue (₦'m) | AA46: ='P&L Input'!C4 -> 1383637 | AB46: ='P&L Input'!D4 -> 1618323 | AC46: ='P&L Input'!E4 -> 2208090 | AD46: ='P&L Input'!F4 -> 3580550 | AE46: ='P&L Input'!G4 -> 4306704 | AF46: =Forecast!E16 -> 5365620.9 | AG46: =Forecast!E17 -> 6194936.5
Z47: Gross Profit (₦'m) | AA47: ='P&L Input'!C6 -> 832618 | AB47: ='P&L Input'!D6 -> 955433 | AC47: ='P&L Input'!E6 -> 1201812 | AD47: ='P&L Input'!F6 -> 1934899 | AE47: ='P&L Input'!G6 -> 2672274 | AF47: not forecast | AG47: not forecast
Z48: EBIT (₦'m) | AA48: ='P&L Input'!C11 -> 582491 | AB48: ='P&L Input'!D11 -> 585876 | AC48: ='P&L Input'!E11 -> 734267 | AD48: ='P&L Input'!F11 -> 1152042 | AE48: ='P&L Input'!G11 -> 1765277 | AF48: not forecast | AG48: not forecast
Z49: Net Income (₦'m) | AA49: ='P&L Input'!C18 -> 364439 | AB49: ='P&L Input'!D18 -> 382311 | AC49: ='P&L Input'!E18 -> 455583 | AD49: ='P&L Input'!F18 -> 503247 | AE49: ='P&L Input'!G18 -> 1014921 | AF49: =Forecast!F16 -> 1360517.5 | AG49: =Forecast!F17 -> 1823794.9
Z54: REVENUE TREND
Z55: Year | AA55: Actual Revenue | AB55: Forecasted Revenue
Z56: 2021 | AA56: =Forecast!C5/1000000 -> 1.383637
Z57: 2022 | AA57: =Forecast!C6/1000000 -> 1.618323
Z58: 2023 | AA58: =Forecast!C7/1000000 -> 2.20809
Z59: 2024 | AA59: =Forecast!C8/1000000 -> 3.58055
Z60: 2025 | AA60: =Forecast!C9/1000000 -> 4.306704 | AB60: =AA60 -> 4.306704
Z61: 2026 | AB61: =Forecast!E16/1000000 -> 5.3656209
Z62: 2027 | AB62: =Forecast!E17/1000000 -> 6.1949365
